Workbook

Sheet Rules_202625
B9: Fantasy Premier League (FPL) Rules
B11: The joining fee is R250 per member. This fee will be used to book a venue where the UEFA Champions League final will be watched.
B12: This joining fee must be paid by 30 September 2025. Failiing to do so will result in gameweek fines being accrued until payment is made. Fine per gameweek is R100.
B13: Each game week, the three teams with the lowest scores will pay R100 each. If there is a tie for either the third, second or first lowest score, all teams tied will pay.
B14: The player with the lowest aggregate score at the end of the season will pay an additional R250.
B15: Male guests who wish to join us and watch along will have to pay the average contribution made throughout the season, which will be determined at the end of the season.
B16: Members who wish to leave after Game week 18 can do so, but they must pay the amount accumulated plus an additional 150% of that amount. They will also not be allowed to attend future events unless they comply with the above rule.
B17: If COVID-19 or a similar event occurs and the games are stopped, the rules will remain in place. No concessions or force majeure will be applied.
B18: The winner of the FPL competition will select alcohol of their choice to be consumed during the Champions League final.
B19: The person at the bottom of the log at the end of GW19 is responsible for finding the venue for the final by 31 January 2026, and this venue must be in Gauteng.
B20: This venue is to be approved by the person at the top of the log at the end of GW19. Failure to find a venue by 31 January 2026 will result in fines being accrued for every gameweek where a venue is not finalised. Fine per gameweek is R100.
B21: The loser of the FPL competition must buy ice from their own personal funds and will be the squire to the winner. If the squire is out of town due to circumstances beyond their control, at the discretion of the board, the duties will fall to the second biggest loser.
... B32: Account holder: SN Zwane Account Name: Capitec Savings Account Number: 1523803027 Branch Code 470010 Ref: Name and "FPL"

Sheet FPL
B2: Rules
B3: Roster
B4: Last Man Paying
B5: Budget

Sheet Roster
B8: No. | C8: Team | D8: Manager | E8: YTD Payment Received | F8: Joining Fee Payment Received | G8: Total | H8: Amount Owing | I8: Bottom 3 appearances
B9: 1 | C9: Learnmore Ntshangase | D9: A Cunha Matata | E9: ='Funds Received'!J4 -> 700 | F9: 250 | G9: =SUM(E9:F9) -> 950 | H9: =VLOOKUP(Roster!C9,Budget!$B:$G,6,)-G9 -> 400 | I9: =COUNTIF('Last Man Paying 2.0'!$E$26:$E$156,Roster!D9) -> 10 | J9: Fine issued for late payment
B10: 2 | C10: Fanele Msweli | D10: Boehlys World Champs | E10: ='Funds Received'!I5+'Funds Received'!G5-Roster!F10 -> 700 | F10: 250 | G10: =SUM(E10:F10) -> 950 | H10: =VLOOKUP(Roster!C10,Budget!$B:$G,6,)-G10 -> 300 | I10: =COUNTIF('Last Man Paying 2.0'!$E$26:$E$156,Roster!D10) -> 10
B11: 3 | C11: Lethu Mkhwanazi | D11: Bruno, dos, tres | E11: ='Funds Received'!J6 -> 200 | F11: 250 | G11: =SUM(E11:F11) -> 450 | H11: =VLOOKUP(Roster!C11,Budget!$B:$G,6,)-G11 -> 600 | I11: =COUNTIF('Last Man Paying 2.0'!$E$26:$E$156,Roster!D11) -> 7 | J11: Fine issued for late payment
B12: 4 | C12: Mhlengi Kunene | D12: Hidden Hills | E12: ='Funds Received'!J7 -> 100 | F12: 250 | G12: =SUM(E12:F12) -> 350 | H12: =VLOOKUP(Roster!C12,Budget!$B:$G,6,)-G12 -> 200 | I12: =COUNTIF('Last Man Paying 2.0'!$E$26:$E$156,Roster!D12) -> 3
B13: 5 | C13: Minenhle Khumalo | D13: Hot Slot FC | E13: ='Funds Received'!J8 -> 700 | F13: 250 | G13: =SUM(E13:F13) -> 950 | H13: =VLOOKUP(Roster!C13,Budget!$B:$G,6,)-G13 -> 500 | I13: =COUNTIF('Last Man Paying 2.0'!$E$26:$E$156,Roster!D13) -> 13
B14: 6 | C14: Nhlakanipho Ntombela | D14: Iam_ntombela | E14: ='Funds Received'!J9+'Funds Received'!I9 -> 300 | F14: 250 | G14: =SUM(E14:F14) -> 550 | H14: =VLOOKUP(Roster!C14,Budget!$B:$G,6,)-G14 -> 100 | I14: =COUNTIF('Last Man Paying 2.0'!$E$26:$E$156,Roster!D14) -> 5
B15: 7 | C15: Mtho Mabizela | D15: Joao Island | E15: ='Funds Received'!I10+'Funds Received'!M10 -> 500 | F15: 250 | G15: =SUM(E15:F15) -> 750 | H15: =VLOOKUP(Roster!C15,Budget!$B:$G,6,)-G15 -> 200 | I15: =COUNTIF('Last Man Paying 2.0'!$E$26:$E$156,Roster!D15) -> 7
B16: 8 | C16: Siyanda Ndaba | D16: JustGimmeDeLigt | E16: ='Funds Received'!J11 -> 400 | F16: 250 | G16: =SUM(E16:F16) -> 650 | H16: =VLOOKUP(Roster!C16,Budget!$B:$G,6,)-G16 -> 400 | I16: =COUNTIF('Last Man Paying 2.0'!$E$26:$E$156,Roster!D16) -> 7 | J16: Fine issued for late payment
B17: 9 | C17: President Gamede | D17: Los Primeros | E17: ='Funds Received'!O12 -> 0 | F17: 0 | G17: =SUM(E17:F17) -> 0 | H17: =VLOOKUP(Roster!C17,Budget!$B:$G,6,)-G17 -> 2150 | I17: =COUNTIF('Last Man Paying 2.0'!$E$26:$E$156,Roster!D17) -> 5 | J17: Fine issued for late payment, GW20 & GW21
B18: 10 | C18: Luthando Ngidi | D18: Palmergeddon | E18: ='Funds Received'!H13+'Funds Received'!I13+'Funds Received'!K13 -> 400 | F18: 250 | G18: =SUM(E18:F18) -> 650 | H18: =VLOOKUP(Roster!C18,Budget!$B:$G,6,)-G18 -> 0 | I18: =COUNTIF('Last Man Paying 2.0'!$E$26:$E$156,Roster!D18) -> 3 | J18: settled his fine
B19: 11 | C19: Kudzai Kupeta | D19: Rice Rice Baby | E19: ='Funds Received'!I14 -> 700 | F19: 250 | G19: =SUM(E19:F19) -> 950 | H19: =VLOOKUP(Roster!C19,Budget!$B:$G,6,)-G19 -> 100 | I19: =COUNTIF('Last Man Paying 2.0'!$E$26:$E$156,Roster!D19) -> 8
B20: 12 | C20: Thembalethu Miya | D20: Root_.5 FC | E20: ='Funds Received'!I15+'Funds Received'!K15 -> 700 | F20: 250 | G20: =SUM(E20:F20) -> 950 | H20: =VLOOKUP(Roster!C20,Budget!$B:$G,6,)-G20 -> 300 | I20: =COUNTIF('Last Man Paying 2.0'!$E$26:$E$156,Roster!D20) -> 10
B21: 13 | C21: Nkosi The Chef | D21: Šeśko Mode | E21: ='Funds Received'!J16 -> 200 | F21: 250 | G21: =SUM(E21:F21) -> 450 | H21: =VLOOKUP(Roster!C21,Budget!$B:$G,6,)-G21 -> 0 | I21: =COUNTIF('Last Man Paying 2.0'!$E$26:$E$156,Roster!D21) -> 1 | J21: Fine issued for late payment
B22: 14 | C22: Sthe Coqueto | D22: Sthe Coqueto | E22: ='Funds Received'!I17 -> 750 | F22: 250 | G22: =SUM(E22:F22) -> 1000 | H22: =VLOOKUP(Roster!C22,Budget!$B:$G,6,)-G22 -> 550 | I22: =COUNTIF('Last Man Paying 2.0'!$E$26:$E$156,Roster!D22) -> 13
B23: 15 | C23: Bheka Bhengu | D23: SzoboSlay | E23: ='Funds Received'!I18 -> 400 | F23: 250 | G23: =SUM(E23:F23) -> 650 | H23: =VLOOKUP(Roster!C23,Budget!$B:$G,6,)-G23 -> 700 | I23: =COUNTIF('Last Man Paying 2.0'!$E$26:$E$156,Roster!D23) -> 9 | J23: Fine issued for late payment, GW20 & GW21
B24: 16 | C24: Thato Choshi | D24: TAYDO FC | E24: ='Funds Received'!M19+'Funds Received'!J19-Roster!F24 -> 800 | F24: 250 | G24: =SUM(E24:F24) -> 1050 | H24: =VLOOKUP(Roster!C24,Budget!$B:$G,6,)-G24 -> 100 | I24: =COUNTIF('Last Man Paying 2.0'!$E$26:$E$156,Roster!D24) -> 8 | J24: Fine issued for late payment, GW20 & GW21
B25: 17 | C25: Mbuyi Katumba | D25: Walala WaSalah | E25: 0 | F25: 250 | G25: =SUM(E25:F25) -> 250 | H25: =VLOOKUP(Roster!C25,Budget!$B:$G,6,)-G25 -> 0 | I25: =COUNTIF('Last Man Paying 2.0'!$E$26:$E$156,Roster!D25) -> 0
E26: =SUM(E9:E25) -> 7550 | F26: =SUM(F9:F25) -> 4000 | H26: =SUM(H9:H25) -> 6600

Sheet Budget
B8: Loser | C8: Amount | D8: Fines | E8: GW20 Fines | F8: GW21 Fines | G8: Total | H8: Amount Paid | I8: Outstanding
B9: Learnmore Ntshangase | C9: =SUMIF('Last Man Paying 2.0'!$D$9:$F$157,B9,'Last Man Paying 2.0'!$F$9:$F$157) -> 1250 | D9: 0 | E9: 100 | F9: 0 | G9: =C9+D9+E9+F9 -> 1350 | H9: =SUMIF('Funds Received'!$C:$C,Budget!B9,'Funds Received'!$O:$O) -> 950 | I9: =G9-H9 -> 400
B10: Fanele Msweli | C10: =SUMIF('Last Man Paying 2.0'!$D$9:$F$157,B10,'Last Man Paying 2.0'!$F$9:$F$157) -> 1250 | D10: 0 | E10: 0 | F10: 0 | G10: =C10+D10+E10+F10 -> 1250 | H10: =SUMIF('Funds Received'!$C:$C,Budget!B10,'Funds Received'!$O:$O) -> 1250 | I10: =G10-H10 -> 0
B11: Lethu Mkhwanazi | C11: =SUMIF('Last Man Paying 2.0'!$D$9:$F$157,B11,'Last Man Paying 2.0'!$F$9:$F$157) -> 950 | D11: 0 | E11: 100 | F11: 0 | G11: =C11+D11+E11+F11 -> 1050 | H11: =SUMIF('Funds Received'!$C:$C,Budget!B11,'Funds Received'!$O:$O) -> 450 | I11: =G11-H11 -> 600
B12: Mhlengi Kunene | C12: =SUMIF('Last Man Paying 2.0'!$D$9:$F$157,B12,'Last Man Paying 2.0'!$F$9:$F$157) -> 550 | D12: 0 | E12: 0 | F12: 0 | G12: =C12+D12+E12+F12 -> 550 | H12: =SUMIF('Funds Received'!$C:$C,Budget!B12,'Funds Received'!$O:$O) -> 550 | I12: =G12-H12 -> 0
B13: Minenhle Khumalo | C13: =SUMIF('Last Man Paying 2.0'!$D$9:$F$157,B13,'Last Man Paying 2.0'!$F$9:$F$157) -> 1450 | D13: 0 | E13: 0 | F13: 0 | G13: =C13+D13+E13+F13 -> 1450 | H13: =SUMIF('Funds Received'!$C:$C,Budget!B13,'Funds Received'!$O:$O) -> 950 | I13: =G13-H13 -> 500
B14: Nhlakanipho Ntombela | C14: =SUMIF('Last Man Paying 2.0'!$D$9:$F$157,B14,'Last Man Paying 2.0'!$F$9:$F$157) -> 650 | D14: 0 | E14: 0 | F14: 0 | G14: =C14+D14+E14+F14 -> 650 | H14: =SUMIF('Funds Received'!$C:$C,Budget!B14,'Funds Received'!$O:$O) -> 550 | I14: =G14-H14 -> 100
B15: Mtho Mabizela | C15: =SUMIF('Last Man Paying 2.0'!$D$9:$F$157,B15,'Last Man Paying 2.0'!$F$9:$F$157) -> 950 | D15: 0 | E15: 0 | F15: 0 | G15: =C15+D15+E15+F15 -> 950 | H15: =SUMIF('Funds Received'!$C:$C,Budget!B15,'Funds Received'!$O:$O) -> 750 | I15: =G15-H15 -> 200
B16: Siyanda Ndaba | C16: =SUMIF('Last Man Paying 2.0'!$D$9:$F$157,B16,'Last Man Paying 2.0'!$F$9:$F$157) -> 950 | D16: 0 | E16: 100 | F16: 0 | G16: =C16+D16+E16+F16 -> 1050 | H16: =SUMIF('Funds Received'!$C:$C,Budget!B16,'Funds Received'!$O:$O) -> 650 | I16: =G16-H16 -> 400
B17: President Gamede | C17: =SUMIF('Last Man Paying 2.0'!$D$9:$F$157,B17,'Last Man Paying 2.0'!$F$9:$F$157) -> 750 | D17: 0 | E17: 100 | F17: =100+1200 -> 1300 | G17: =C17+D17+E17+F17 -> 2150 | H17: =SUMIF('Funds Received'!$C:$C,Budget!B17,'Funds Received'!$O:$O) -> 0 | I17: =G17-H17 -> 2150
B18: Luthando Ngidi | C18: =SUMIF('Last Man Paying 2.0'!$D$9:$F$157,B18,'Last Man Paying 2.0'!$F$9:$F$157) -> 550 | D18: 100 | E18: 0 | F18: 0 | G18: =C18+D18+E18+F18 -> 650 | H18: =SUMIF('Funds Received'!$C:$C,Budget!B18,'Funds Received'!$O:$O) -> 650 | I18: =G18-H18 -> 0
B19: Kudzai Kupeta | C19: =SUMIF('Last Man Paying 2.0'!$D$9:$F$157,B19,'Last Man Paying 2.0'!$F$9:$F$157) -> 1050 | D19: 0 | E19: 0 | F19: 0 | G19: =C19+D19+E19+F19 -> 1050 | H19: =SUMIF('Funds Received'!$C:$C,Budget!B19,'Funds Received'!$O:$O) -> 1050 | I19: =G19-H19 -> 0
B20: Thembalethu Miya | C20: =SUMIF('Last Man Paying 2.0'!$D$9:$F$157,B20,'Last Man Paying 2.0'!$F$9:$F$157) -> 1250 | D20: 0 | E20: 0 | F20: 0 | G20: =C20+D20+E20+F20 -> 1250 | H20: =SUMIF('Funds Received'!$C:$C,Budget!B20,'Funds Received'!$O:$O) -> 950 | I20: =G20-H20 -> 300
B21: Nkosi The Chef | C21: =SUMIF('Last Man Paying 2.0'!$D$9:$F$157,B21,'Last Man Paying 2.0'!$F$9:$F$157) -> 350 | D21: 0 | E21: 100 | F21: 0 | G21: =C21+D21+E21+F21 -> 450 | H21: =SUMIF('Funds Received'!$C:$C,Budget!B21,'Funds Received'!$O:$O) -> 450 | I21: =G21-H21 -> 0
B22: Sthe Coqueto | C22: =SUMIF('Last Man Paying 2.0'!$D$9:$F$157,B22,'Last Man Paying 2.0'!$F$9:$F$157) -> 1550 | D22: 0 | E22: 0 | F22: 0 | G22: =C22+D22+E22+F22 -> 1550 | H22: =SUMIF('Funds Received'!$C:$C,Budget!B22,'Funds Received'!$O:$O) -> 1000 | I22: =G22-H22 -> 550
B23: Bheka Bhengu | C23: =SUMIF('Last Man Paying 2.0'!$D$9:$F$157,B23,'Last Man Paying 2.0'!$F$9:$F$157) -> 1150 | D23: 0 | E23: 100 | F23: 100 | G23: =C23+D23+E23+F23 -> 1350 | H23: =SUMIF('Funds Received'!$C:$C,Budget!B23,'Funds Received'!$O:$O) -> 650 | I23: =G23-H23 -> 700
B24: Thato Choshi | C24: =SUMIF('Last Man Paying 2.0'!$D$9:$F$157,B24,'Last Man Paying 2.0'!$F$9:$F$157) -> 950 | D24: 0 | E24: 100 | F24: 100 | G24: =C24+D24+E24+F24 -> 1150 | H24: =SUMIF('Funds Received'!$C:$C,Budget!B24,'Funds Received'!$O:$O) -> 1050 | I24: =G24-H24 -> 100
B25: Mbuyi Katumba | C25: =SUMIF('Last Man Paying 2.0'!$D$9:$F$157,B25,'Last Man Paying 2.0'!$F$9:$F$157) -> 250 | D25: 0 | E25: 0 | F25: 0 | G25: =C25+D25+E25+F25 -> 250 | H25: =SUMIF('Funds Received'!$C:$C,Budget!B25,'Funds Received'!$O:$O) -> 250 | I25: =G25-H25 -> 0
B27: Total | C27: =SUM(C9:C25) -> 15850 | G27: =SUM(G9:G25) -> 18150 | I27: =SUM(I9:I25) -> 6000
B29: Average | C29: =AVERAGE(C9:C25) -> 932.35294 | G29: =AVERAGE(G9:G25) -> 1067.6471

Sheet Sheet1

Sheet Last Man Paying 2.0
B8: Gameweek | C8: No. | D8: Loser | E8: Team | F8: Amount | G8: Payment status
D9: Learnmore Ntshangase | E9: =IFERROR(VLOOKUP(D9,Roster!$C$8:$D$25,2,),"To be determined") -> A Cunha Matata | F9: 250 | G9: Outstanding | T9: Paid
D10: Fanele Msweli | E10: =IFERROR(VLOOKUP(D10,Roster!$C$8:$D$25,2,),"To be determined") -> Boehlys World Champs | F10: 250 | G10: Outstanding | T10: Outstanding
D11: Lethu Mkhwanazi | E11: =IFERROR(VLOOKUP(D11,Roster!$C$8:$D$25,2,),"To be determined") -> Bruno, dos, tres | F11: 250 | G11: Outstanding
D12: Mhlengi Kunene | E12: =IFERROR(VLOOKUP(D12,Roster!$C$8:$D$25,2,),"To be determined") -> Hidden Hills | F12: 250 | G12: Outstanding
D13: Minenhle Khumalo | E13: =IFERROR(VLOOKUP(D13,Roster!$C$8:$D$25,2,),"To be determined") -> Hot Slot FC | F13: 250 | G13: Outstanding
D14: Nhlakanipho Ntombela | E14: =IFERROR(VLOOKUP(D14,Roster!$C$8:$D$25,2,),"To be determined") -> Iam_ntombela | F14: 250 | G14: Outstanding
D15: Mtho Mabizela | E15: =IFERROR(VLOOKUP(D15,Roster!$C$8:$D$25,2,),"To be determined") -> Joao Island | F15: 250 | G15: Outstanding
D16: Siyanda Ndaba | E16: =IFERROR(VLOOKUP(D16,Roster!$C$8:$D$25,2,),"To be determined") -> JustGimmeDeLigt | F16: 250 | G16: Outstanding
D17: President Gamede | E17: =IFERROR(VLOOKUP(D17,Roster!$C$8:$D$25,2,),"To be determined") -> Los Primeros | F17: 250 | G17: Outstanding
D18: Luthando Ngidi | E18: =IFERROR(VLOOKUP(D18,Roster!$C$8:$D$25,2,),"To be determined") -> Palmergeddon | F18: 250 | G18: Outstanding
D19: Kudzai Kupeta | E19: =IFERROR(VLOOKUP(D19,Roster!$C$8:$D$25,2,),"To be determined") -> Rice Rice Baby | F19: 250 | G19: Outstanding
D20: Thembalethu Miya | E20: =IFERROR(VLOOKUP(D20,Roster!$C$8:$D$25,2,),"To be determined") -> Root_.5 FC | F20: 250 | G20: Outstanding
D21: Nkosi The Chef | E21: =IFERROR(VLOOKUP(D21,Roster!$C$8:$D$25,2,),"To be determined") -> Šeśko Mode | F21: 250 | G21: Outstanding
D22: Sthe Coqueto | E22: =IFERROR(VLOOKUP(D22,Roster!$C$8:$D$25,2,),"To be determined") -> Sthe Coqueto | F22: 250 | G22: Outstanding
... D25: Mbuyi Katumba | E25: =IFERROR(VLOOKUP(D25,Roster!$C$8:$D$25,2,),"To be determined") -> Walala WaSalah | F25: 250 | G25: Outstanding
B26: GW 1 | C26: 1 | D26: Sthe Coqueto | E26: =IFERROR(VLOOKUP(D26,Roster!$C$8:$D$25,2,),"To be determined") -> Sthe Coqueto | F26: 100 | G26: Outstanding
C27: 2 | D27: Minenhle Khumalo | E27: =IFERROR(VLOOKUP(D27,Roster!$C$8:$D$25,2,),"To be determined") -> Hot Slot FC | F27: 100 | G27: Outstanding
C28: 3 | D28: Lethu Mkhwanazi | E28: =IFERROR(VLOOKUP(D28,Roster!$C$8:$D$25,2,),"To be determined") -> Bruno, dos, tres | F28: 100 | G28: Outstanding
C29: 4 | D29: Learnmore Ntshangase | E29: =IFERROR(VLOOKUP(D29,Roster!$C$8:$D$25,2,),"To be determined") -> A Cunha Matata | F29: 100 | G29: Outstanding
B30: GW 2 | C30: 1 | D30: Sthe Coqueto | E30: =IFERROR(VLOOKUP(D30,Roster!$C$8:$D$25,2,),"To be determined") -> Sthe Coqueto | F30: 100 | G30: Outstanding
C31: 2 | D31: Mhlengi Kunene | E31: =IFERROR(VLOOKUP(D31,Roster!$C$8:$D$25,2,),"To be determined") -> Hidden Hills | F31: 100 | G31: Outstanding
C32: 3 | D32: Thembalethu Miya | E32: =IFERROR(VLOOKUP(D32,Roster!$C$8:$D$25,2,),"To be determined") -> Root_.5 FC | F32: 100 | G32: Outstanding
B33: GW 3 | C33: 1 | D33: Minenhle Khumalo | E33: =IFERROR(VLOOKUP(D33,Roster!$C$8:$D$25,2,),"To be determined") -> Hot Slot FC | F33: 100 | G33: Outstanding
C34: 2 | D34: Thembalethu Miya | E34: =IFERROR(VLOOKUP(D34,Roster!$C$8:$D$25,2,),"To be determined") -> Root_.5 FC | F34: 100 | G34: Outstanding
C35: 3 | D35: Kudzai Kupeta | E35: =IFERROR(VLOOKUP(D35,Roster!$C$8:$D$25,2,),"To be determined") -> Rice Rice Baby | F35: 100 | G35: Outstanding
B36: GW 4 | C36: 1 | D36: Sthe Coqueto | E36: =IFERROR(VLOOKUP(D36,Roster!$C$8:$D$25,2,),"To be determined") -> Sthe Coqueto | F36: 100 | G36: Outstanding
C37: 2 | D37: Bheka Bhengu | E37: =IFERROR(VLOOKUP(D37,Roster!$C$8:$D$25,2,),"To be determined") -> SzoboSlay | F37: 100 | G37: Outstanding
C38: 3 | D38: Learnmore Ntshangase | E38: =IFERROR(VLOOKUP(D38,Roster!$C$8:$D$25,2,),"To be determined") -> A Cunha Matata | F38: 100 | G38: Outstanding
C39: 4 | D39: Nhlakanipho Ntombela | E39: =IFERROR(VLOOKUP(D39,Roster!$C$8:$D$25,2,),"To be determined") -> Iam_ntombela | F39: 100 | G39: Outstanding
B40: GW 5 | C40: 1 | D40: Fanele Msweli | E40: =IFERROR(VLOOKUP(D40,Roster!$C$8:$D$25,2,),"To be determined") -> Boehlys World Champs | F40: 100 | G40: Outstanding
C41: 2 | D41: President Gamede | E41: =IFERROR(VLOOKUP(D41,Roster!$C$8:$D$25,2,),"To be determined") -> Los Primeros | F41: 100 | G41: Outstanding
C42: 3 | D42: Kudzai Kupeta | E42: =IFERROR(VLOOKUP(D42,Roster!$C$8:$D$25,2,),"To be determined") -> Rice Rice Baby | F42: 100 | G42: Outstanding
B43: GW 6 | C43: 1 | D43: Minenhle Khumalo | E43: =IFERROR(VLOOKUP(D43,Roster!$C$8:$D$25,2,),"To be determined") -> Hot Slot FC | F43: 100 | G43: Outstanding
C44: 2 | D44: Learnmore Ntshangase | E44: =IFERROR(VLOOKUP(D44,Roster!$C$8:$D$25,2,),"To be determined") -> A Cunha Matata | F44: 100 | G44: Outstanding
C45: 3 | D45: Thato Choshi | E45: =IFERROR(VLOOKUP(D45,Roster!$C$8:$D$25,2,),"To be determined") -> TAYDO FC | F45: 100 | G45: Outstanding
B46: GW 7 | C46: 1 | D46: Mtho Mabizela | E46: =IFERROR(VLOOKUP(D46,Roster!$C$8:$D$25,2,),"To be determined") -> Joao Island | F46: 100 | G46: Outstanding
C47: 2 | D47: Fanele Msweli | E47: =IFERROR(VLOOKUP(D47,Roster!$C$8:$D$25,2,),"To be determined") -> Boehlys World Champs | F47: 100 | G47: Outstanding
C48: 3 | D48: Lethu Mkhwanazi | E48: =IFERROR(VLOOKUP(D48,Roster!$C$8:$D$25,2,),"To be determined") -> Bruno, dos, tres | F48: 100 | G48: Outstanding
B49: GW 8 | C49: 1 | D49: Mtho Mabizela | E49: =IFERROR(VLOOKUP(D49,Roster!$C$8:$D$25,2,),"To be determined") -> Joao Island | F49: 100 | G49: Outstanding
...

Sheet Stats
CJ7: 3 | CK7: =CJ7 -> 3 | CL7: 41
B8: No. | C8: Team | D8: Manager | E8: GW1 | F8: GW2 | G8: GW3 | H8: GW4 | I8: GW5 | J8: GW6 | K8: GW7 | L8: GW8 | M8: GW9 | N8: GW10 | O8: GW11 | P8: GW12 | Q8: GW13 | R8: GW14 | S8: GW15 | T8: GW16 | U8: GW17 | V8: GW18 | W8: GW19 | X8: GW20 | Y8: GW21 | Z8: GW22 | AA8: GW23 | AB8: GW24 | AC8: GW25 | AD8: GW26 | AE8: GW27 | AF8: GW28 | AG8: GW29 | AH8: GW30 | AI8: GW31 | AJ8: GW32 | AK8: GW33 | AL8: GW34 | AM8: GW35 | AN8: GW36 | AO8: GW37 | AP8: GW38 | AQ8: Total | AS8: Team | AT8: Manager | AU8: GW1 | AV8: GW2 | AW8: GW3 | AX8: GW4 | AY8: GW5 | AZ8: GW6 | BA8: GW7 | BB8: GW8 | BC8: GW9 | BD8: GW10 | BE8: GW11 | BF8: GW12 | BG8: GW13 | BH8: GW14 | BI8: GW15 | BJ8: GW16 | BK8: GW17 | BL8: GW18 | BM8: GW19 | BN8: GW20 | BO8: GW21 | BP8: GW22 | BQ8: GW23 | BR8: GW24 | BS8: GW25 | BT8: GW26 | BU8: GW27 | BV8: GW28 | BW8: GW29 | BX8: GW30 | BY8: GW31 | BZ8: GW32 | CA8: GW33 | CB8: GW34 | CC8: GW35 | CD8: GW36 | CE8: GW37 | CF8: GW38 | CH8: Team | CI8: Manager | CJ8: Points | CK8: Position | CL8: YTD Points
A9: A Cunha Matata (Learnmore Ntshangase) | B9: 1 | C9: Learnmore Ntshangase | D9: A Cunha Matata | E9: 47 | F9: 47 | G9: 50 | H9: 59 | I9: 57 | J9: 26 | K9: 87 | L9: 72 | M9: 38 | N9: 54 | O9: 50 | P9: 35 | Q9: 26 | R9: 63 | S9: 56 | T9: 78 | U9: 69 | V9: 33 | W9: 27 | X9: 57 | Y9: 66 | Z9: 33 | AA9: 54 | AB9: 40 | AC9: 75 | AD9: 47 | AE9: 52 | AF9: 75 | AG9: 50 | AH9: 51 | AI9: 62 | AJ9: 45 | AK9: 78 | AL9: 51 | AM9: 0 | AN9: 0 | AO9: 0 | AP9: 0 | AQ9: =SUM(E9:AP9) -> 1810 | AS9: Learnmore Ntshangase | AT9: A Cunha Matata | AU9: =RANK(E9,E$9:E$25,) -> 14 | AV9: =RANK(F9,F$9:F$25,) -> 11 | AW9: =RANK(G9,G$9:G$25,) -> 6 | AX9: =RANK(H9,H$9:H$25,) -> 14 | AY9: =RANK(I9,I$9:I$25,) -> 3 | AZ9: =RANK(J9,J$9:J$25,) -> 16 | BA9: =RANK(K9,K$9:K$25,) -> 1 | BB9: =RANK(L9,L$9:L$25,) -> 2 | ... CF9: =RANK(AP9,AP$9:AP$25,) -> 1 | CH9: Learnmore Ntshangase | CI9: A Cunha Matata | CJ9: =VLOOKUP(CH9,$C$8:$AQ$25,$CJ$7,) -> 47 | CK9: =VLOOKUP(CH9,$AS$8:$CF$25,$CK$7,) -> 14 | CL9: =VLOOKUP(CH9,$C$8:$AQ$25,$CL$7,) -> 1810
A10: Boehlys World Champs (Fanele Msweli) | B10: 2 | C10: Fanele Msweli | D10: Boehlys World Champs | E10: 64 | F10: 54 | G10: 52 | H10: 78 | I10: 30 | J10: 44 | K10: 53 | L10: 60 | M10: 43 | N10: 57 | O10: 28 | P10: 48 | Q10: 29 | R10: 68 | S10: 42 | T10: 54 | U10: 67 | V10: 52 | W10: 38 | X10: 54 | Y10: 51 | Z10: 32 | AA10: 56 | AB10: 52 | AC10: 68 | AD10: 50 | AE10: 41 | AF10: 76 | AG10: 79 | AH10: 48 | AI10: 44 | AJ10: 59 | AK10: 52 | AL10: 74 | AM10: 0 | AN10: 0 | AO10: 0 | AP10: 0 | AQ10: =SUM(E10:AP10) -> 1797 | AS10: Fanele Msweli | AT10: Boehlys World Champs | AU10: =RANK(E10,E$9:E$25,) -> 3 | AV10: =RANK(F10,F$9:F$25,) -> 3 | AW10: =RANK(G10,G$9:G$25,) -> 5 | AX10: =RANK(H10,H$9:H$25,) -> 3 | AY10: =RANK(I10,I$9:I$25,) -> 17 | AZ10: =RANK(J10,J$9:J$25,) -> 13 | BA10: =RANK(K10,K$9:K$25,) -> 16 | BB10: =RANK(L10,L$9:L$25,) -> 6 | ... CF10: =RANK(AP10,AP$9:AP$25,) -> 1 | CH10: Fanele Msweli | CI10: Boehlys World Champs | CJ10: =VLOOKUP(CH10,$C$8:$AQ$25,$CJ$7,) -> 64 | CK10: =VLOOKUP(CH10,$AS$8:$CF$25,$CK$7,) -> 3 | CL10: =VLOOKUP(CH10,$C$8:$AQ$25,$CL$7,) -> 1797
A11: Bruno, dos, tres (Lethu Mkhwanazi) | B11: 3 | C11: Lethu Mkhwanazi | D11: Bruno, dos, tres | E11: 43 | F11: 39 | G11: 70 | H11: 71 | I11: 54 | J11: 45 | K11: 55 | L11: 60 | M11: 45 | N11: 84 | O11: 34 | P11: 39 | Q11: 48 | R11: 80 | S11: 71 | T11: 92 | U11: 100 | V11: 43 | W11: 38 | X11: 44 | Y11: 48 | Z11: 51 | AA11: 29 | AB11: 64 | AC11: 63 | AD11: 53 | AE11: 30 | AF11: 66 | AG11: 68 | AH11: 49 | AI11: 63 | AJ11: 41 | AK11: 87 | AL11: 41 | AM11: 0 | AN11: 0 | AO11: 0 | AP11: 0 | AQ11: =SUM(E11:AP11) -> 1908 | AS11: Lethu Mkhwanazi | AT11: Bruno, dos, tres | AU11: =RANK(E11,E$9:E$25,) -> 15 | AV11: =RANK(F11,F$9:F$25,) -> 14 | AW11: =RANK(G11,G$9:G$25,) -> 1 | AX11: =RANK(H11,H$9:H$25,) -> 7 | AY11: =RANK(I11,I$9:I$25,) -> 5 | AZ11: =RANK(J11,J$9:J$25,) -> 12 | BA11: =RANK(K11,K$9:K$25,) -> 15 | BB11: =RANK(L11,L$9:L$25,) -> 6 | ... CF11: =RANK(AP11,AP$9:AP$25,) -> 1 | CH11: Lethu Mkhwanazi | CI11: Bruno, dos, tres | CJ11: =VLOOKUP(CH11,$C$8:$AQ$25,$CJ$7,) -> 43 | CK11: =VLOOKUP(CH11,$AS$8:$CF$25,$CK$7,) -> 15 | CL11: =VLOOKUP(CH11,$C$8:$AQ$25,$CL$7,) -> 1908
A12: Hidden Hills (Mhlengi Kunene) | B12: 4 | C12: Mhlengi Kunene | D12: Hidden Hills | E12: 62 | F12: 37 | G12: 56 | H12: 69 | I12: 76 | J12: 78 | K12: 79 | L12: 57 | M12: 42 | N12: 71 | O12: 36 | P12: 38 | Q12: 50 | R12: 56 | S12: 60 | T12: 64 | U12: 79 | V12: 39 | W12: 37 | X12: 44 | Y12: 53 | Z12: 31 | AA12: 49 | AB12: 53 | AC12: 74 | AD12: 67 | AE12: 52 | AF12: 66 | AG12: 79 | AH12: 47 | AI12: 48 | AJ12: 66 | AK12: 115 | AL12: 65 | AM12: 0 | AN12: 0 | AO12: 0 | AP12: 0 | AQ12: =SUM(E12:AP12) -> 1995 | AS12: Mhlengi Kunene | AT12: Hidden Hills | AU12: =RANK(E12,E$9:E$25,) -> 6 | AV12: =RANK(F12,F$9:F$25,) -> 16 | AW12: =RANK(G12,G$9:G$25,) -> 2 | AX12: =RANK(H12,H$9:H$25,) -> 9 | AY12: =RANK(I12,I$9:I$25,) -> 1 | AZ12: =RANK(J12,J$9:J$25,) -> 1 | BA12: =RANK(K12,K$9:K$25,) -> 4 | BB12: =RANK(L12,L$9:L$25,) -> 11 | ... CF12: =RANK(AP12,AP$9:AP$25,) -> 1 | CH12: Mhlengi Kunene | CI12: Hidden Hills | CJ12: =VLOOKUP(CH12,$C$8:$AQ$25,$CJ$7,) -> 62 | CK12: =VLOOKUP(CH12,$AS$8:$CF$25,$CK$7,) -> 6 | CL12: =VLOOKUP(CH12,$C$8:$AQ$25,$CL$7,) -> 1995
A13: Hot Slot FC (Minenhle Khumalo) | B13: 5 | C13: Minenhle Khumalo | D13: Hot Slot FC | E13: 43 | F13: 42 | G13: 34 | H13: 73 | I13: 52 | J13: 21 | K13: 86 | L13: 57 | M13: 34 | N13: 65 | O13: 43 | P13: 28 | Q13: 27 | R13: 53 | S13: 47 | T13: 63 | U13: 78 | V13: 43 | W13: 33 | X13: 53 | Y13: 71 | Z13: 35 | AA13: 56 | AB13: 52 | AC13: 49 | AD13: 55 | AE13: 54 | AF13: 59 | AG13: 51 | AH13: 39 | AI13: 51 | AJ13: 42 | AK13: 83 | AL13: 45 | AM13: 0 | AN13: 0 | AO13: 0 | AP13: 0 | AQ13: =SUM(E13:AP13) -> 1717 | AS13: Minenhle Khumalo | AT13: Hot Slot FC | AU13: =RANK(E13,E$9:E$25,) -> 15 | AV13: =RANK(F13,F$9:F$25,) -> 13 | AW13: =RANK(G13,G$9:G$25,) -> 17 | AX13: =RANK(H13,H$9:H$25,) -> 6 | AY13: =RANK(I13,I$9:I$25,) -> 6 | AZ13: =RANK(J13,J$9:J$25,) -> 17 | BA13: =RANK(K13,K$9:K$25,) -> 3 | BB13: =RANK(L13,L$9:L$25,) -> 11 | ... CF13: =RANK(AP13,AP$9:AP$25,) -> 1 | CH13: Minenhle Khumalo | CI13: Hot Slot FC | CJ13: =VLOOKUP(CH13,$C$8:$AQ$25,$CJ$7,) -> 43 | CK13: =VLOOKUP(CH13,$AS$8:$CF$25,$CK$7,) -> 15 | CL13: =VLOOKUP(CH13,$C$8:$AQ$25,$CL$7,) -> 1717
A14: Iam_ntombela (Nhlakanipho Ntombela) | B14: 6 | C14: Nhlakanipho Ntombela | D14: Iam_ntombela | E14: 55 | F14: 53 | G14: 44 | H14: 59 | I14: 41 | J14: 70 | K14: 87 | L14: 91 | M14: 43 | N14: 78 | O14: 38 | P14: 34 | Q14: 60 | R14: 75 | S14: 52 | T14: 73 | U14: 65 | V14: 36 | W14: 40 | X14: 56 | Y14: 51 | Z14: 40 | AA14: 22 | AB14: 75 | AC14: 69 | AD14: 71 | AE14: 40 | AF14: 79 | AG14: 63 | AH14: 48 | AI14: 55 | AJ14: 65 | AK14: 121 | AL14: 56 | AM14: 0 | AN14: 0 | AO14: 0 | AP14: 0 | AQ14: =SUM(E14:AP14) -> 2005 | AS14: Nhlakanipho Ntombela | AT14: Iam_ntombela | AU14: =RANK(E14,E$9:E$25,) -> 10 | AV14: =RANK(F14,F$9:F$25,) -> 5 | AW14: =RANK(G14,G$9:G$25,) -> 12 | AX14: =RANK(H14,H$9:H$25,) -> 14 | AY14: =RANK(I14,I$9:I$25,) -> 13 | AZ14: =RANK(J14,J$9:J$25,) -> 2 | BA14: =RANK(K14,K$9:K$25,) -> 1 | BB14: =RANK(L14,L$9:L$25,) -> 1 | ... CF14: =RANK(AP14,AP$9:AP$25,) -> 1 | CH14: Nhlakanipho Ntombela | CI14: Iam_ntombela | CJ14: =VLOOKUP(CH14,$C$8:$AQ$25,$CJ$7,) -> 55 | CK14: =VLOOKUP(CH14,$AS$8:$CF$25,$CK$7,) -> 10 | CL14: =VLOOKUP(CH14,$C$8:$AQ$25,$CL$7,) -> 2005
A15: Joao Island (Mtho Mabizela) | B15: 7 | C15: Mtho Mabizela | D15: Joao Island | E15: 58 | F15: 45 | G15: 41 | H15: 66 | I15: 50 | J15: 38 | K15: 46 | L15: 46 | M15: 52 | N15: 64 | O15: 38 | P15: 24 | Q15: 34 | R15: 74 | S15: 67 | T15: 85 | U15: 80 | V15: 34 | W15: 31 | X15: 41 | Y15: 59 | Z15: 38 | AA15: 48 | AB15: 44 | AC15: 68 | AD15: 55 | AE15: 44 | AF15: 79 | AG15: 82 | AH15: 55 | AI15: 59 | AJ15: 52 | AK15: 82 | AL15: 46 | AM15: 0 | AN15: 0 | AO15: 0 | AP15: 0 | AQ15: =SUM(E15:AP15) -> 1825 | AS15: Mtho Mabizela | AT15: Joao Island | AU15: =RANK(E15,E$9:E$25,) -> 7 | AV15: =RANK(F15,F$9:F$25,) -> 12 | AW15: =RANK(G15,G$9:G$25,) -> 14 | AX15: =RANK(H15,H$9:H$25,) -> 10 | AY15: =RANK(I15,I$9:I$25,) -> 9 | AZ15: =RANK(J15,J$9:J$25,) -> 14 | BA15: =RANK(K15,K$9:K$25,) -> 17 | BB15: =RANK(L15,L$9:L$25,) -> 17 | ... CF15: =RANK(AP15,AP$9:AP$25,) -> 1 | CH15: Mtho Mabizela | CI15: Joao Island | CJ15: =VLOOKUP(CH15,$C$8:$AQ$25,$CJ$7,) -> 58 | CK15: =VLOOKUP(CH15,$AS$8:$CF$25,$CK$7,) -> 7 | CL15: =VLOOKUP(CH15,$C$8:$AQ$25,$CL$7,) -> 1825
A16: JustGimmeDeLigt (Siyanda Ndaba) | B16: 8 | C16: Siyanda Ndaba | D16: JustGimmeDeLigt | E16: 56 | F16: 60 | G16: 47 | H16: 63 | I16: 45 | J16: 62 | K16: 64 | L16: 53 | M16: 51 | N16: 68 | O16: 53 | P16: 29 | Q16: 50 | R16: 87 | S16: 57 | T16: 76 | U16: 74 | V16: 40 | W16: 26 | X16: 49 | Y16: 56 | Z16: 27 | AA16: 44 | AB16: 59 | AC16: 80 | AD16: 44 | AE16: 34 | AF16: 79 | AG16: 74 | AH16: 61 | AI16: 55 | AJ16: 44 | AK16: 112 | AL16: 71 | AM16: 0 | AN16: 0 | AO16: 0 | AP16: 0 | AQ16: =SUM(E16:AP16) -> 1950 | AS16: Siyanda Ndaba | AT16: JustGimmeDeLigt | AU16: =RANK(E16,E$9:E$25,) -> 8 | AV16: =RANK(F16,F$9:F$25,) -> 2 | AW16: =RANK(G16,G$9:G$25,) -> 8 | AX16: =RANK(H16,H$9:H$25,) -> 13 | AY16: =RANK(I16,I$9:I$25,) -> 12 | AZ16: =RANK(J16,J$9:J$25,) -> 4 | BA16: =RANK(K16,K$9:K$25,) -> 10 | BB16: =RANK(L16,L$9:L$25,) -> 14 | ... CF16: =RANK(AP16,AP$9:AP$25,) -> 1 | CH16: Siyanda Ndaba | CI16: JustGimmeDeLigt | CJ16: =VLOOKUP(CH16,$C$8:$AQ$25,$CJ$7,) -> 56 | CK16: =VLOOKUP(CH16,$AS$8:$CF$25,$CK$7,) -> 8 | CL16: =VLOOKUP(CH16,$C$8:$AQ$25,$CL$7,) -> 1950
A17: Los Primeros (President Gamede) | B17: 9 | C17: President Gamede | D17: Los Primeros | E17: 56 | F17: 49 | G17: 50 | H17: 75 | I17: 32 | J17: 53 | K17: 63 | L17: 56 | M17: 49 | N17: 53 | O17: 40 | P17: 33 | Q17: 30 | R17: 57 | S17: 46 | T17: 76 | U17: 64 | V17: 42 | W17: 57 | X17: 43 | Y17: 60 | Z17: 46 | AA17: 31 | AB17: 71 | AC17: 76 | AD17: 70 | AE17: 46 | AF17: 67 | AG17: 69 | AH17: 50 | AI17: 50 | AJ17: 61 | AK17: 74 | AL17: 22 | AM17: 0 | AN17: 0 | AO17: 0 | AP17: 0 | AQ17: =SUM(E17:AP17) -> 1817 | AS17: President Gamede | AT17: Los Primeros | AU17: =RANK(E17,E$9:E$25,) -> 8 | AV17: =RANK(F17,F$9:F$25,) -> 9 | AW17: =RANK(G17,G$9:G$25,) -> 6 | AX17: =RANK(H17,H$9:H$25,) -> 5 | AY17: =RANK(I17,I$9:I$25,) -> 16 | AZ17: =RANK(J17,J$9:J$25,) -> 9 | BA17: =RANK(K17,K$9:K$25,) -> 11 | BB17: =RANK(L17,L$9:L$25,) -> 13 | ... CF17: =RANK(AP17,AP$9:AP$25,) -> 1 | CH17: President Gamede | CI17: Los Primeros | CJ17: =VLOOKUP(CH17,$C$8:$AQ$25,$CJ$7,) -> 56 | CK17: =VLOOKUP(CH17,$AS$8:$CF$25,$CK$7,) -> 8 | CL17: =VLOOKUP(CH17,$C$8:$AQ$25,$CL$7,) -> 1817
A18: Palmergeddon (Luthando Ngidi) | B18: 10 | C18: Luthando Ngidi | D18: Palmergeddon | E18: 63 | F18: 53 | G18: 46 | H18: 70 | I18: 50 | J18: 59 | K18: 77 | L18: 58 | M18: 57 | N18: 89 | O18: 39 | P18: 71 | Q18: 17 | R18: 47 | S18: 61 | T18: 67 | U18: 82 | V18: 45 | W18: 49 | X18: 67 | Y18: 51 | Z18: 34 | AA18: 42 | AB18: 52 | AC18: 72 | AD18: 66 | AE18: 38 | AF18: 64 | AG18: 68 | AH18: 61 | AI18: 55 | AJ18: 50 | AK18: 91 | AL18: 58 | AM18: 0 | AN18: 0 | AO18: 0 | AP18: 0 | AQ18: =SUM(E18:AP18) -> 1969 | AS18: Luthando Ngidi | AT18: Palmergeddon | AU18: =RANK(E18,E$9:E$25,) -> 4 | AV18: =RANK(F18,F$9:F$25,) -> 5 | AW18: =RANK(G18,G$9:G$25,) -> 9 | AX18: =RANK(H18,H$9:H$25,) -> 8 | AY18: =RANK(I18,I$9:I$25,) -> 9 | AZ18: =RANK(J18,J$9:J$25,) -> 5 | BA18: =RANK(K18,K$9:K$25,) -> 5 | BB18: =RANK(L18,L$9:L$25,) -> 9 | ... CF18: =RANK(AP18,AP$9:AP$25,) -> 1 | CH18: Luthando Ngidi | CI18: Palmergeddon | CJ18: =VLOOKUP(CH18,$C$8:$AQ$25,$CJ$7,) -> 63 | CK18: =VLOOKUP(CH18,$AS$8:$CF$25,$CK$7,) -> 4 | CL18: =VLOOKUP(CH18,$C$8:$AQ$25,$CL$7,) -> 1969
A19: Rice Rice Baby (Kudzai Kupeta) | B19: 11 | C19: Kudzai Kupeta | D19: Rice Rice Baby | E19: 50 | F19: 64 | G19: 36 | H19: 65 | I19: 34 | J19: 46 | K19: 67 | L19: 58 | M19: 46 | N19: 67 | O19: 25 | P19: 29 | Q19: 34 | R19: 70 | S19: 39 | T19: 73 | U19: 80 | V19: 31 | W19: 33 | X19: 33 | Y19: 69 | Z19: 41 | AA19: 33 | AB19: 45 | AC19: 65 | AD19: 74 | AE19: 44 | AF19: 70 | AG19: 53 | AH19: 76 | AI19: 53 | AJ19: 66 | AK19: 67 | AL19: 55 | AM19: 0 | AN19: 0 | AO19: 0 | AP19: 0 | AQ19: =SUM(E19:AP19) -> 1791 | AS19: Kudzai Kupeta | AT19: Rice Rice Baby | AU19: =RANK(E19,E$9:E$25,) -> 13 | AV19: =RANK(F19,F$9:F$25,) -> 1 | AW19: =RANK(G19,G$9:G$25,) -> 15 | AX19: =RANK(H19,H$9:H$25,) -> 11 | AY19: =RANK(I19,I$9:I$25,) -> 15 | AZ19: =RANK(J19,J$9:J$25,) -> 11 | BA19: =RANK(K19,K$9:K$25,) -> 7 | BB19: =RANK(L19,L$9:L$25,) -> 9 | ... CF19: =RANK(AP19,AP$9:AP$25,) -> 1 | CH19: Kudzai Kupeta | CI19: Rice Rice Baby | CJ19: =VLOOKUP(CH19,$C$8:$AQ$25,$CJ$7,) -> 50 | CK19: =VLOOKUP(CH19,$AS$8:$CF$25,$CK$7,) -> 13 | CL19: =VLOOKUP(CH19,$C$8:$AQ$25,$CL$7,) -> 1791
A20: Root_.5 FC (Thembalethu Miya) | B20: 12 | C20: Thembalethu Miya | D20: Root_.5 FC | E20: 52 | F20: 38 | G20: 35 | H20: 64 | I20: 55 | J20: 53 | K20: 62 | L20: 51 | M20: 29 | N20: 58 | O20: 29 | P20: 45 | Q20: 59 | R20: 55 | S20: 53 | T20: 76 | U20: 79 | V20: 55 | W20: 39 | X20: 42 | Y20: 64 | Z20: 31 | AA20: 57 | AB20: 45 | AC20: 80 | AD20: 45 | AE20: 37 | AF20: 62 | AG20: 74 | AH20: 46 | AI20: 51 | AJ20: 66 | AK20: 80 | AL20: 52 | AM20: 0 | AN20: 0 | AO20: 0 | AP20: 0 | AQ20: =SUM(E20:AP20) -> 1819 | AS20: Thembalethu Miya | AT20: Root_.5 FC | AU20: =RANK(E20,E$9:E$25,) -> 12 | AV20: =RANK(F20,F$9:F$25,) -> 15 | AW20: =RANK(G20,G$9:G$25,) -> 16 | AX20: =RANK(H20,H$9:H$25,) -> 12 | AY20: =RANK(I20,I$9:I$25,) -> 4 | AZ20: =RANK(J20,J$9:J$25,) -> 9 | BA20: =RANK(K20,K$9:K$25,) -> 12 | BB20: =RANK(L20,L$9:L$25,) -> 16 | ... CF20: =RANK(AP20,AP$9:AP$25,) -> 1 | CH20: Thembalethu Miya | CI20: Root_.5 FC | CJ20: =VLOOKUP(CH20,$C$8:$AQ$25,$CJ$7,) -> 52 | CK20: =VLOOKUP(CH20,$AS$8:$CF$25,$CK$7,) -> 12 | CL20: =VLOOKUP(CH20,$C$8:$AQ$25,$CL$7,) -> 1819
... A25: Walala WaSalah (Mbuyi Katumba) | B25: 17 | C25: Mbuyi Katumba | D25: Walala WaSalah | E25: 66 | F25: 54 | G25: 46 | H25: 78 | I25: 66 | J25: 59 | K25: 58 | L25: 60 | M25: 40 | N25: 78 | O25: 45 | P25: 37 | Q25: 40 | R25: 73 | S25: 57 | T25: 62 | U25: 77 | V25: 45 | W25: 32 | X25: 51 | Y25: 62 | Z25: 39 | AA25: 38 | AB25: 64 | AC25: 65 | AD25: 63 | AE25: 42 | AF25: 77 | AG25: 74 | AH25: 49 | AI25: 52 | AJ25: 58 | AK25: 109 | AL25: 56 | AM25: 0 | AN25: 0 | AO25: 0 | AP25: 0 | AQ25: =SUM(E25:AP25) -> 1972 | AS25: Mbuyi Katumba | AT25: Walala WaSalah | AU25: =RANK(E25,E$9:E$25,) -> 2 | AV25: =RANK(F25,F$9:F$25,) -> 3 | AW25: =RANK(G25,G$9:G$25,) -> 9 | AX25: =RANK(H25,H$9:H$25,) -> 3 | AY25: =RANK(I25,I$9:I$25,) -> 2 | AZ25: =RANK(J25,J$9:J$25,) -> 5 | BA25: =RANK(K25,K$9:K$25,) -> 14 | BB25: =RANK(L25,L$9:L$25,) -> 6 | ... CF25: =RANK(AP25,AP$9:AP$25,) -> 1 | CH25: Mbuyi Katumba | CI25: Walala WaSalah | CJ25: =VLOOKUP(CH25,$C$8:$AQ$25,$CJ$7,) -> 66 | CK25: =VLOOKUP(CH25,$AS$8:$CF$25,$CK$7,) -> 2 | CL25: =VLOOKUP(CH25,$C$8:$AQ$25,$CL$7,) -> 1972
D27: League total | E27: =SUM(E9:E25) -> 935 | F27: =SUM(F9:F25) -> 822 | G27: =SUM(G9:G25) -> 804 | H27: =SUM(H9:H25) -> 1154 | I27: =SUM(I9:I25) -> 829 | J27: =SUM(J9:J25) -> 866 | K27: =SUM(K9:K25) -> 1143 | L27: =SUM(L9:L25) -> 1027 | ... AP27: =SUM(AP9:AP25) -> 0 | AQ27: =SUM(E27:AP27) -> 31933
D28: Average | E28: =AVERAGE(E9:E25) -> 55 | F28: =AVERAGE(F9:F25) -> 48.352941 | G28: =AVERAGE(G9:G25) -> 47.294118 | H28: =AVERAGE(H9:H25) -> 67.882353 | I28: =AVERAGE(I9:I25) -> 48.764706 | J28: =AVERAGE(J9:J25) -> 50.941176 | K28: =AVERAGE(K9:K25) -> 67.235294 | L28: =AVERAGE(L9:L25) -> 60.411765 | ... AP28: =AVERAGE(AP9:AP25) -> 0
D29: Median | E29: =MEDIAN(E9:E25) -> 56 | F29: =MEDIAN(F9:F25) -> 49 | G29: =MEDIAN(G9:G25) -> 46 | H29: =MEDIAN(H9:H25) -> 69 | I29: =MEDIAN(I9:I25) -> 50 | J29: =MEDIAN(J9:J25) -> 53 | K29: =MEDIAN(K9:K25) -> 65 | L29: =MEDIAN(L9:L25) -> 58 | ... AP29: =MEDIAN(AP9:AP25) -> 0
D30: Highest | E30: =MAX(E9:E25) -> 68 | F30: =MAX(F9:F25) -> 64 | G30: =MAX(G9:G25) -> 70 | H30: =MAX(H9:H25) -> 87 | I30: =MAX(I9:I25) -> 76 | J30: =MAX(J9:J25) -> 78 | K30: =MAX(K9:K25) -> 87 | L30: =MAX(L9:L25) -> 91 | ... AP30: =MAX(AP9:AP25) -> 0
D31: Lowest | E31: =MIN(E9:E25) -> 34 | F31: =MIN(F9:F25) -> 35 | G31: =MIN(G9:G25) -> 34 | H31: =MIN(H9:H25) -> 47 | I31: =MIN(I9:I25) -> 30 | J31: =MIN(J9:J25) -> 21 | K31: =MIN(K9:K25) -> 46 | L31: =MIN(L9:L25) -> 46 | ... AP31: =MIN(AP9:AP25) -> 0
D33: Lowest 1 | E33: =SMALL($E$9:$E$25,1) -> 34 | F33: =SMALL(F$9:F$25,1) -> 35 | G33: =SMALL(G$9:G$25,1) -> 34 | H33: =SMALL(H$9:H$25,1) -> 47 | I33: =SMALL(I$9:I$25,1) -> 30 | J33: =SMALL(J$9:J$25,1) -> 21 | K33: =SMALL(K$9:K$25,1) -> 46 | L33: =SMALL(L$9:L$25,1) -> 46 | M33: =SMALL(M$9:M$25,1) -> 29 | ... AP33: =SMALL(AP$9:AP$25,1) -> 0
D34: Lowest 2 | E34: =SMALL($E$9:$E$25,2) -> 43 | F34: =SMALL(F$9:F$25,2) -> 37 | G34: =SMALL(G$9:G$25,2) -> 35 | H34: =SMALL(H$9:H$25,2) -> 51 | I34: =SMALL(I$9:I$25,2) -> 32 | J34: =SMALL(J$9:J$25,2) -> 26 | K34: =SMALL(K$9:K$25,2) -> 53 | L34: =SMALL(L$9:L$25,2) -> 51 | M34: =SMALL(M$9:M$25,2) -> 34 | ... AP34: =SMALL(AP$9:AP$25,2) -> 0
D35: Lowest 3 | E35: =SMALL($E$9:$E$25,3) -> 43 | F35: =SMALL(F$9:F$25,3) -> 38 | G35: =SMALL(G$9:G$25,3) -> 36 | H35: =SMALL(H$9:H$25,3) -> 59 | I35: =SMALL(I$9:I$25,3) -> 34 | J35: =SMALL(J$9:J$25,3) -> 29 | K35: =SMALL(K$9:K$25,3) -> 55 | L35: =SMALL(L$9:L$25,3) -> 53 | M35: =SMALL(M$9:M$25,3) -> 37 | ... AP35: =SMALL(AP$9:AP$25,3) -> 0
D36: Lowest 4 | E36: =SMALL($E$9:$E$25,4) -> 47 | F36: =SMALL(F$9:F$25,4) -> 39 | G36: =SMALL(G$9:G$25,4) -> 41 | H36: =SMALL(H$9:H$25,4) -> 59 | I36: =SMALL(I$9:I$25,4) -> 37 | J36: =SMALL(J$9:J$25,4) -> 38 | K36: =SMALL(K$9:K$25,4) -> 58 | L36: =SMALL(L$9:L$25,4) -> 53 | M36: =SMALL(M$9:M$25,4) -> 38 | ... AP36: =SMALL(AP$9:AP$25,4) -> 0
D37: Lowest 5 | E37: =SMALL($E$9:$E$25,5) -> 50 | F37: =SMALL(F$9:F$25,5) -> 42 | G37: =SMALL(G$9:G$25,5) -> 43 | H37: =SMALL(H$9:H$25,5) -> 63 | I37: =SMALL(I$9:I$25,5) -> 41 | J37: =SMALL(J$9:J$25,5) -> 44 | K37: =SMALL(K$9:K$25,5) -> 60 | L37: =SMALL(L$9:L$25,5) -> 56 | M37: =SMALL(M$9:M$25,5) -> 40 | ... AP37: =SMALL(AP$9:AP$25,5) -> 0
D38: Lowest 6 | E38: =SMALL($E$9:$E$25,6) -> 52 | F38: =SMALL(F$9:F$25,6) -> 45 | G38: =SMALL(G$9:G$25,6) -> 44 | H38: =SMALL(H$9:H$25,6) -> 64 | I38: =SMALL(I$9:I$25,6) -> 45 | J38: =SMALL(J$9:J$25,6) -> 45 | K38: =SMALL(K$9:K$25,6) -> 62 | L38: =SMALL(L$9:L$25,6) -> 57 | M38: =SMALL(M$9:M$25,6) -> 42 | ... AP38: =SMALL(AP$9:AP$25,6) -> 0
D39: Lowest 7 | E39: =SMALL($E$9:$E$25,7) -> 55 | F39: =SMALL(F$9:F$25,7) -> 47 | G39: =SMALL(G$9:G$25,7) -> 45 | H39: =SMALL(H$9:H$25,7) -> 65 | I39: =SMALL(I$9:I$25,7) -> 46 | J39: =SMALL(J$9:J$25,7) -> 46 | K39: =SMALL(K$9:K$25,7) -> 63 | L39: =SMALL(L$9:L$25,7) -> 57 | M39: =SMALL(M$9:M$25,7) -> 42 | ... AP39: =SMALL(AP$9:AP$25,7) -> 0
D40: Lowest 8 | E40: =SMALL($E$9:$E$25,8) -> 55 | F40: =SMALL(F$9:F$25,8) -> 48 | G40: =SMALL(G$9:G$25,8) -> 46 | H40: =SMALL(H$9:H$25,8) -> 66 | I40: =SMALL(I$9:I$25,8) -> 50 | J40: =SMALL(J$9:J$25,8) -> 53 | K40: =SMALL(K$9:K$25,8) -> 64 | L40: =SMALL(L$9:L$25,8) -> 58 | M40: =SMALL(M$9:M$25,8) -> 43 | ... AP40: =SMALL(AP$9:AP$25,8) -> 0
D41: Lowest 9 | E41: =SMALL($E$9:$E$25,9) -> 56 | F41: =SMALL(F$9:F$25,9) -> 49 | G41: =SMALL(G$9:G$25,9) -> 46 | H41: =SMALL(H$9:H$25,9) -> 69 | I41: =SMALL(I$9:I$25,9) -> 50 | J41: =SMALL(J$9:J$25,9) -> 53 | K41: =SMALL(K$9:K$25,9) -> 65 | L41: =SMALL(L$9:L$25,9) -> 58 | M41: =SMALL(M$9:M$25,9) -> 43 | ... AP41: =SMALL(AP$9:AP$25,9) -> 0
D42: Lowest 10 | E42: =SMALL($E$9:$E$25,10) -> 56 | F42: =SMALL(F$9:F$25,10) -> 52 | G42: =SMALL(G$9:G$25,10) -> 47 | H42: =SMALL(H$9:H$25,10) -> 70 | I42: =SMALL(I$9:I$25,10) -> 52 | J42: =SMALL(J$9:J$25,10) -> 56 | K42: =SMALL(K$9:K$25,10) -> 65 | L42: =SMALL(L$9:L$25,10) -> 60 | M42: =SMALL(M$9:M$25,10) -> 44 | ... AP42: =SMALL(AP$9:AP$25,10) -> 0
D43: Lowest 11 | E43: =SMALL($E$9:$E$25,11) -> 58 | F43: =SMALL(F$9:F$25,11) -> 52 | G43: =SMALL(G$9:G$25,11) -> 50 | H43: =SMALL(H$9:H$25,11) -> 71 | I43: =SMALL(I$9:I$25,11) -> 52 | J43: =SMALL(J$9:J$25,11) -> 57 | K43: =SMALL(K$9:K$25,11) -> 67 | L43: =SMALL(L$9:L$25,11) -> 60 | M43: =SMALL(M$9:M$25,11) -> 45 | ... AP43: =SMALL(AP$9:AP$25,11) -> 0
D44: Lowest 12 | E44: =SMALL($E$9:$E$25,12) -> 62 | F44: =SMALL(F$9:F$25,12) -> 53 | G44: =SMALL(G$9:G$25,12) -> 50 | H44: =SMALL(H$9:H$25,12) -> 73 | I44: =SMALL(I$9:I$25,12) -> 52 | J44: =SMALL(J$9:J$25,12) -> 59 | K44: =SMALL(K$9:K$25,12) -> 69 | L44: =SMALL(L$9:L$25,12) -> 60 | M44: =SMALL(M$9:M$25,12) -> 46 | ... AP44: =SMALL(AP$9:AP$25,12) -> 0
D45: Lowest 13 | E45: =SMALL($E$9:$E$25,13) -> 63 | F45: =SMALL(F$9:F$25,13) -> 53 | G45: =SMALL(G$9:G$25,13) -> 52 | H45: =SMALL(H$9:H$25,13) -> 75 | I45: =SMALL(I$9:I$25,13) -> 54 | J45: =SMALL(J$9:J$25,13) -> 59 | K45: =SMALL(K$9:K$25,13) -> 77 | L45: =SMALL(L$9:L$25,13) -> 62 | M45: =SMALL(M$9:M$25,13) -> 49 | ... AP45: =SMALL(AP$9:AP$25,13) -> 0
D46: Lowest 14 | E46: =SMALL($E$9:$E$25,14) -> 63 | F46: =SMALL(F$9:F$25,14) -> 54 | G46: =SMALL(G$9:G$25,14) -> 54 | H46: =SMALL(H$9:H$25,14) -> 78 | I46: =SMALL(I$9:I$25,14) -> 55 | J46: =SMALL(J$9:J$25,14) -> 62 | K46: =SMALL(K$9:K$25,14) -> 79 | L46: =SMALL(L$9:L$25,14) -> 66 | M46: =SMALL(M$9:M$25,14) -> 51 | ... AP46: =SMALL(AP$9:AP$25,14) -> 0
D47: Lowest 15 | E47: =SMALL($E$9:$E$25,14) -> 63 | F47: =SMALL(F$9:F$25,15) -> 54 | G47: =SMALL(G$9:G$25,15) -> 55 | H47: =SMALL(H$9:H$25,15) -> 78 | I47: =SMALL(I$9:I$25,15) -> 57 | J47: =SMALL(J$9:J$25,15) -> 70 | K47: =SMALL(K$9:K$25,15) -> 86 | L47: =SMALL(L$9:L$25,15) -> 67 | M47: =SMALL(M$9:M$25,15) -> 52 | ... AP47: =SMALL(AP$9:AP$25,15) -> 0
D48: Lowest 16 | E48: =SMALL($E$9:$E$25,16) -> 66 | F48: =SMALL(F$9:F$25,16) -> 60 | G48: =SMALL(G$9:G$25,16) -> 56 | H48: =SMALL(H$9:H$25,16) -> 79 | I48: =SMALL(I$9:I$25,16) -> 66 | J48: =SMALL(J$9:J$25,16) -> 70 | K48: =SMALL(K$9:K$25,16) -> 87 | L48: =SMALL(L$9:L$25,16) -> 72 | M48: =SMALL(M$9:M$25,16) -> 53 | ... AP48: =SMALL(AP$9:AP$25,16) -> 0
D49: Lowest 17 | E49: =SMALL($E$9:$E$25,17) -> 68 | F49: =SMALL(F$9:F$25,17) -> 64 | G49: =SMALL(G$9:G$25,17) -> 70 | H49: =SMALL(H$9:H$25,17) -> 87 | I49: =SMALL(I$9:I$25,17) -> 76 | J49: =SMALL(J$9:J$25,17) -> 78 | K49: =SMALL(K$9:K$25,17) -> 87 | L49: =SMALL(L$9:L$25,17) -> 91 | M49: =SMALL(M$9:M$25,17) -> 57 | ... AP49: =SMALL(AP$9:AP$25,17) -> 0

Sheet Sheet2
B2: Team | C2: Manager | D2: Total
B3: Nkosi The Chef | C3: Šeśko Mode | D3: 2084
B4: Nhlakanipho Ntombela | C4: Iam_ntombela | D4: 2005
B5: Mhlengi Kunene | C5: Hidden Hills | D5: 1995
B6: Mbuyi Katumba | C6: Walala WaSalah | D6: 1972
B7: Luthando Ngidi | C7: Palmergeddon | D7: 1969
B8: Siyanda Ndaba | C8: JustGimmeDeLigt | D8: 1950
B9: Lethu Mkhwanazi | C9: Bruno, dos, tres | D9: 1908
B10: Thato Choshi | C10: TAYDO FC | D10: 1868
B11: Bheka Bhengu | C11: SzoboSlay | D11: 1864
B12: Mtho Mabizela | C12: Joao Island | D12: 1825
B13: Thembalethu Miya | C13: Root_.5 FC | D13: 1819
B14: President Gamede | C14: Los Primeros | D14: 1817
... B19: Minenhle Khumalo | C19: Hot Slot FC | D19: 1717

Sheet Funds Received
B2: No. | C2: Team | D2: Manager | E2: Month Funds Received
E3: August | F3: September | G3: October | H3: November | I3: December | J3: January | K3: February | L3: March | M3: April | N3: May | O3: Total
B4: 1 | C4: Learnmore Ntshangase | D4: A Cunha Matata | F4: 250 | J4: 700 | O4: =SUM(E4:N4) -> 950
B5: 2 | C5: Fanele Msweli | D5: Boehlys World Champs | G5: =250+200 -> 450 | I5: 500 | M5: 300 | O5: =SUM(E5:N5) -> 1250
B6: 3 | C6: Lethu Mkhwanazi | D6: Bruno, dos, tres | G6: 250 | J6: 200 | O6: =SUM(E6:N6) -> 450
B7: 4 | C7: Mhlengi Kunene | D7: Hidden Hills | F7: 250 | J7: 100 | M7: 200 | O7: =SUM(E7:N7) -> 550
B8: 5 | C8: Minenhle Khumalo | D8: Hot Slot FC | G8: 250 | J8: 700 | O8: =SUM(E8:N8) -> 950
B9: 6 | C9: Nhlakanipho Ntombela | D9: Iam_ntombela | F9: 250 | I9: 100 | J9: =100+100 -> 200 | O9: =SUM(E9:N9) -> 550
B10: 7 | C10: Mtho Mabizela | D10: Joao Island | E10: 250 | I10: 300 | M10: 200 | O10: =SUM(E10:N10) -> 750
B11: 8 | C11: Siyanda Ndaba | D11: JustGimmeDeLigt | G11: 250 | J11: =300+100 -> 400 | O11: =SUM(E11:N11) -> 650
B12: 9 | C12: President Gamede | D12: Los Primeros | O12: =SUM(E12:N12) -> 0
B13: 10 | C13: Luthando Ngidi | D13: Palmergeddon | G13: 250 | H13: 100 | I13: 200 | K13: 100 | O13: =SUM(E13:N13) -> 650
B14: 11 | C14: Kudzai Kupeta | D14: Rice Rice Baby | F14: 350 | I14: 700 | O14: =SUM(E14:N14) -> 1050
B15: 12 | C15: Thembalethu Miya | D15: Root_.5 FC | F15: 250 | I15: =500+100 -> 600 | K15: 100 | O15: =SUM(E15:N15) -> 950
B16: 13 | C16: Nkosi The Chef | D16: Šeśko Mode | G16: 250 | J16: 200 | O16: =SUM(E16:N16) -> 450
B17: 14 | C17: Sthe Coqueto | D17: Sthe Coqueto | G17: 250 | I17: 750 | O17: =SUM(E17:N17) -> 1000
B18: 15 | C18: Bheka Bhengu | D18: SzoboSlay | G18: 250 | I18: 400 | O18: =SUM(E18:N18) -> 650
B19: 16 | C19: Thato Choshi | D19: TAYDO FC | J19: 650 | M19: 400 | O19: =SUM(E19:N19) -> 1050
B20: 17 | C20: Mbuyi Katumba | D20: Walala WaSalah | E20: 250 | O20: =SUM(E20:N20) -> 250
O21: =SUM(O4:O20) -> 12150
